Workbook

Sheet Start here
A1: McCormack's website: which products go on which page
A2: Some pages on the new website are empty because nothing has been placed on them yet. We need a pharmacist or a senior member of staff to tell us which products belong on each one.
A4: What to do
A5: 1. Open the tab 'Pages to fill'. Each page on the website has a list of products we think might belong there. For each product, choose Yes or No in the yellow column 'Belongs on this page?'.
A6: 2. Each page ends with two empty yellow rows. If a product we sell is missing from the list, type its name there and choose Yes.
A7: 3. Open the tab 'Confirm Medicines & Health'. These are products we have already matched to a page and need a pharmacist to check before they go live. Choose Yes or No in the yellow column.
A8: 4. Only fill in the yellow cells. Leave everything else as it is. The table below shows how far you have got.
A9: 5. Send the file back to us. We make the changes; nothing on the website changes until then.
A10: 6. Three more tabs. 'Medicine classification' lists the 346 products the website treats as medicines. Every order for any of them will wait for a pharmacist before it is sent, as PSI guidance requires, so this is not a shortlist. For each, tell us whether our classification is right by choosing Pharmacy-only, General sale, Veterinary medicine or Not a medicine. The five flea treatments are already filled in as Veterinary medicine; change them if we are wrong. The first 219 are licensed on the HPRA register; the rest need your judgement. Every product stays marked as a medicine whatever you choose: if you choose Not a medicine, we will check it with you before changing anything. 'Check licence' has one product whose licence we could not match: tell us how it is licensed. 'Decisions' has five questions: four about particular medicines and one about a quantity-limit app. They are also in the pharmacist questions document.
A11: Example
A12: Page on the website | B12: Product | C12: Belongs here?
A13: Condoms | B13: Durex Extra Safe 12Pk | C13: Yes
A14: Condoms | B14: Durex Play 50Ml Feel Lube | C14: No
A15: The second example is No because lubricant is not a condom; it belongs under Sexual Health instead.
A17: Progress
A18: Pages to fill | B18: Department | C18: Products | D18: Answered | E18: Yes
A19: Ladies Fragrance Sets | B19: Fragrance | C19: =COUNTIFS('Pages to fill'!$B$2:$B$340,A19,'Pages to fill'!$C$2:$C$340,"<>") | D19: =COUNTIFS('Pages to fill'!$B$2:$B$340,A19,'Pages to fill'!$C$2:$C$340,"<>",'Pages to fill'!$E$2:$E$340,"<>") | E19: =COUNTIFS('Pages to fill'!$B$2:$B$340,A19,'Pages to fill'!$E$2:$E$340,"Yes")
A20: Ladies Fragrance Singles | B20: Fragrance | C20: =COUNTIFS('Pages to fill'!$B$2:$B$340,A20,'Pages to fill'!$C$2:$C$340,"<>") | D20: =COUNTIFS('Pages to fill'!$B$2:$B$340,A20,'Pages to fill'!$C$2:$C$340,"<>",'Pages to fill'!$E$2:$E$340,"<>") | E20: =COUNTIFS('Pages to fill'!$B$2:$B$340,A20,'Pages to fill'!$E$2:$E$340,"Yes")
A21: Mens Fragrance Sets | B21: Fragrance | C21: =COUNTIFS('Pages to fill'!$B$2:$B$340,A21,'Pages to fill'!$C$2:$C$340,"<>") | D21: =COUNTIFS('Pages to fill'!$B$2:$B$340,A21,'Pages to fill'!$C$2:$C$340,"<>",'Pages to fill'!$E$2:$E$340,"<>") | E21: =COUNTIFS('Pages to fill'!$B$2:$B$340,A21,'Pages to fill'!$E$2:$E$340,"Yes")
A22: Mens Fragrance Singles | B22: Fragrance | C22: =COUNTIFS('Pages to fill'!$B$2:$B$340,A22,'Pages to fill'!$C$2:$C$340,"<>") | D22: =COUNTIFS('Pages to fill'!$B$2:$B$340,A22,'Pages to fill'!$C$2:$C$340,"<>",'Pages to fill'!$E$2:$E$340,"<>") | E22: =COUNTIFS('Pages to fill'!$B$2:$B$340,A22,'Pages to fill'!$E$2:$E$340,"Yes")
A23: Baby & Children Pain Relief | B23: Medicines & Health | C23: =COUNTIFS('Pages to fill'!$B$2:$B$340,A23,'Pages to fill'!$C$2:$C$340,"<>") | D23: =COUNTIFS('Pages to fill'!$B$2:$B$340,A23,'Pages to fill'!$C$2:$C$340,"<>",'Pages to fill'!$E$2:$E$340,"<>") | E23: =COUNTIFS('Pages to fill'!$B$2:$B$340,A23,'Pages to fill'!$E$2:$E$340,"Yes")
A24: Bladder Weakness | B24: Medicines & Health | C24: =COUNTIFS('Pages to fill'!$B$2:$B$340,A24,'Pages to fill'!$C$2:$C$340,"<>") | D24: =COUNTIFS('Pages to fill'!$B$2:$B$340,A24,'Pages to fill'!$C$2:$C$340,"<>",'Pages to fill'!$E$2:$E$340,"<>") | E24: =COUNTIFS('Pages to fill'!$B$2:$B$340,A24,'Pages to fill'!$E$2:$E$340,"Yes")
A25: Bloating & Gas | B25: Medicines & Health | C25: =COUNTIFS('Pages to fill'!$B$2:$B$340,A25,'Pages to fill'!$C$2:$C$340,"<>") | D25: =COUNTIFS('Pages to fill'!$B$2:$B$340,A25,'Pages to fill'!$C$2:$C$340,"<>",'Pages to fill'!$E$2:$E$340,"<>") | E25: =COUNTIFS('Pages to fill'!$B$2:$B$340,A25,'Pages to fill'!$E$2:$E$340,"Yes")
A26: Cold Therapy & Heat Therapy | B26: Medicines & Health | C26: =COUNTIFS('Pages to fill'!$B$2:$B$340,A26,'Pages to fill'!$C$2:$C$340,"<>") | D26: =COUNTIFS('Pages to fill'!$B$2:$B$340,A26,'Pages to fill'!$C$2:$C$340,"<>",'Pages to fill'!$E$2:$E$340,"<>") | E26: =COUNTIFS('Pages to fill'!$B$2:$B$340,A26,'Pages to fill'!$E$2:$E$340,"Yes")
A27: Condoms | B27: Medicines & Health | C27: =COUNTIFS('Pages to fill'!$B$2:$B$340,A27,'Pages to fill'!$C$2:$C$340,"<>") | D27: =COUNTIFS('Pages to fill'!$B$2:$B$340,A27,'Pages to fill'!$C$2:$C$340,"<>",'Pages to fill'!$E$2:$E$340,"<>") | E27: =COUNTIFS('Pages to fill'!$B$2:$B$340,A27,'Pages to fill'!$E$2:$E$340,"Yes")
A28: Constipation | B28: Medicines & Health | C28: =COUNTIFS('Pages to fill'!$B$2:$B$340,A28,'Pages to fill'!$C$2:$C$340,"<>") | D28: =COUNTIFS('Pages to fill'!$B$2:$B$340,A28,'Pages to fill'!$C$2:$C$340,"<>",'Pages to fill'!$E$2:$E$340,"<>") | E28: =COUNTIFS('Pages to fill'!$B$2:$B$340,A28,'Pages to fill'!$E$2:$E$340,"Yes")
A29: Cramping & Irritable Bowel | B29: Medicines & Health | C29: =COUNTIFS('Pages to fill'!$B$2:$B$340,A29,'Pages to fill'!$C$2:$C$340,"<>") | D29: =COUNTIFS('Pages to fill'!$B$2:$B$340,A29,'Pages to fill'!$C$2:$C$340,"<>",'Pages to fill'!$E$2:$E$340,"<>") | E29: =COUNTIFS('Pages to fill'!$B$2:$B$340,A29,'Pages to fill'!$E$2:$E$340,"Yes")
A30: Cystitis | B30: Medicines & Health | C30: =COUNTIFS('Pages to fill'!$B$2:$B$340,A30,'Pages to fill'!$C$2:$C$340,"<>") | D30: =COUNTIFS('Pages to fill'!$B$2:$B$340,A30,'Pages to fill'!$C$2:$C$340,"<>",'Pages to fill'!$E$2:$E$340,"<>") | E30: =COUNTIFS('Pages to fill'!$B$2:$B$340,A30,'Pages to fill'!$E$2:$E$340,"Yes")
... A47: Supports | B47: Medicines & Health | C47: =COUNTIFS('Pages to fill'!$B$2:$B$340,A47,'Pages to fill'!$C$2:$C$340,"<>") | D47: =COUNTIFS('Pages to fill'!$B$2:$B$340,A47,'Pages to fill'!$C$2:$C$340,"<>",'Pages to fill'!$E$2:$E$340,"<>") | E47: =COUNTIFS('Pages to fill'!$B$2:$B$340,A47,'Pages to fill'!$E$2:$E$340,"Yes")
A49: Confirm Medicines & Health | C49: Products | D49: Answered | E49: Yes
A50: Antiseptics & Wound Cleaning | C50: =COUNTIFS('Confirm Medicines & Health'!$A$2:$A$121,A50,'Confirm Medicines & Health'!$B$2:$B$121,"<>") | D50: =COUNTIFS('Confirm Medicines & Health'!$A$2:$A$121,A50,'Confirm Medicines & Health'!$B$2:$B$121,"<>",'Confirm Medicines & Health'!$E$2:$E$121,"<>") | E50: =COUNTIFS('Confirm Medicines & Health'!$A$2:$A$121,A50,'Confirm Medicines & Health'!$E$2:$E$121,"Yes")
A51: Athletes Foot | C51: =COUNTIFS('Confirm Medicines & Health'!$A$2:$A$121,A51,'Confirm Medicines & Health'!$B$2:$B$121,"<>") | D51: =COUNTIFS('Confirm Medicines & Health'!$A$2:$A$121,A51,'Confirm Medicines & Health'!$B$2:$B$121,"<>",'Confirm Medicines & Health'!$E$2:$E$121,"<>") | E51: =COUNTIFS('Confirm Medicines & Health'!$A$2:$A$121,A51,'Confirm Medicines & Health'!$E$2:$E$121,"Yes")
A52: Bandages & Plasters | C52: =COUNTIFS('Confirm Medicines & Health'!$A$2:$A$121,A52,'Confirm Medicines & Health'!$B$2:$B$121,"<>") | D52: =COUNTIFS('Confirm Medicines & Health'!$A$2:$A$121,A52,'Confirm Medicines & Health'!$B$2:$B$121,"<>",'Confirm Medicines & Health'!$E$2:$E$121,"<>") | E52: =COUNTIFS('Confirm Medicines & Health'!$A$2:$A$121,A52,'Confirm Medicines & Health'!$E$2:$E$121,"Yes")
A53: Blepharitis & Eyelid Hygiene | C53: =COUNTIFS('Confirm Medicines & Health'!$A$2:$A$121,A53,'Confirm Medicines & Health'!$B$2:$B$121,"<>") | D53: =COUNTIFS('Confirm Medicines & Health'!$A$2:$A$121,A53,'Confirm Medicines & Health'!$B$2:$B$121,"<>",'Confirm Medicines & Health'!$E$2:$E$121,"<>") | E53: =COUNTIFS('Confirm Medicines & Health'!$A$2:$A$121,A53,'Confirm Medicines & Health'!$E$2:$E$121,"Yes")
A54: Blisters & Bunion Care | C54: =COUNTIFS('Confirm Medicines & Health'!$A$2:$A$121,A54,'Confirm Medicines & Health'!$B$2:$B$121,"<>") | D54: =COUNTIFS('Confirm Medicines & Health'!$A$2:$A$121,A54,'Confirm Medicines & Health'!$B$2:$B$121,"<>",'Confirm Medicines & Health'!$E$2:$E$121,"<>") | E54: =COUNTIFS('Confirm Medicines & Health'!$A$2:$A$121,A54,'Confirm Medicines & Health'!$E$2:$E$121,"Yes")
A55: Blocked Nose & Sinus | C55: =COUNTIFS('Confirm Medicines & Health'!$A$2:$A$121,A55,'Confirm Medicines & Health'!$B$2:$B$121,"<>") | D55: =COUNTIFS('Confirm Medicines & Health'!$A$2:$A$121,A55,'Confirm Medicines & Health'!$B$2:$B$121,"<>",'Confirm Medicines & Health'!$E$2:$E$121,"<>") | E55: =COUNTIFS('Confirm Medicines & Health'!$A$2:$A$121,A55,'Confirm Medicines & Health'!$E$2:$E$121,"Yes")
A56: Chiropody Felt & Padding | C56: =COUNTIFS('Confirm Medicines & Health'!$A$2:$A$121,A56,'Confirm Medicines & Health'!$B$2:$B$121,"<>") | D56: =COUNTIFS('Confirm Medicines & Health'!$A$2:$A$121,A56,'Confirm Medicines & Health'!$B$2:$B$121,"<>",'Confirm Medicines & Health'!$E$2:$E$121,"<>") | E56: =COUNTIFS('Confirm Medicines & Health'!$A$2:$A$121,A56,'Confirm Medicines & Health'!$E$2:$E$121,"Yes")
A57: Cold & Flu Combination Products | C57: =COUNTIFS('Confirm Medicines & Health'!$A$2:$A$121,A57,'Confirm Medicines & Health'!$B$2:$B$121,"<>") | D57: =COUNTIFS('Confirm Medicines & Health'!$A$2:$A$121,A57,'Confirm Medicines & Health'!$B$2:$B$121,"<>",'Confirm Medicines & Health'!$E$2:$E$121,"<>") | E57: =COUNTIFS('Confirm Medicines & Health'!$A$2:$A$121,A57,'Confirm Medicines & Health'!$E$2:$E$121,"Yes")
A58: Continence Care | C58: =COUNTIFS('Confirm Medicines & Health'!$A$2:$A$121,A58,'Confirm Medicines & Health'!$B$2:$B$121,"<>") | D58: =COUNTIFS('Confirm Medicines & Health'!$A$2:$A$121,A58,'Confirm Medicines & Health'!$B$2:$B$121,"<>",'Confirm Medicines & Health'!$E$2:$E$121,"<>") | E58: =COUNTIFS('Confirm Medicines & Health'!$A$2:$A$121,A58,'Confirm Medicines & Health'!$E$2:$E$121,"Yes")
A59: Corn & Callous Care | C59: =COUNTIFS('Confirm Medicines & Health'!$A$2:$A$121,A59,'Confirm Medicines & Health'!$B$2:$B$121,"<>") | D59: =COUNTIFS('Confirm Medicines & Health'!$A$2:$A$121,A59,'Confirm Medicines & Health'!$B$2:$B$121,"<>",'Confirm Medicines & Health'!$E$2:$E$121,"<>") | E59: =COUNTIFS('Confirm Medicines & Health'!$A$2:$A$121,A59,'Confirm Medicines & Health'!$E$2:$E$121,"Yes")
...

Sheet Pages to fill
A1: Department | B1: Page on the website | C1: Product | D1: Brand | E1: Belongs on this page? | F1: Notes (optional)
A2: Fragrance | B2: Ladies Fragrance Sets | C2: Boss Alive Ladies 30Ml 2Pc Gift Set | D2: Hugo Boss
A3: Fragrance | B3: Ladies Fragrance Sets | C3: Ck Eternity Ladies 50Ml 3Pc Gift Set | D3: CALVIN KLEIN
A4: Fragrance | B4: Ladies Fragrance Sets | C4: Cool Water Ladies 30Ml 2Pc Gift Set | D4: McCormack's Pharmacy
A5: Fragrance | B5: Ladies Fragrance Sets | C5: Gucci Guilty Pour Femme 50Ml 2Pc Gift Set | D5: Gucci
A6: Fragrance | B6: Ladies Fragrance Sets | C6: Jimmy Choo I Want Choo 60Ml 2Pc Gift Set | D6: Jimmy Choo
A7: Fragrance | B7: Ladies Fragrance Sets | C7: Jimmy Choo I Want Choo Forever 60Ml 2Pc Gift Set | D7: Jimmy Choo
A8: Fragrance | B8: Ladies Fragrance Sets | C8: Jimmy Choo Rose Passion 60Ml 2Pc Gift Set | D8: Jimmy Choo
A9: Fragrance | B9: Ladies Fragrance Sets | C9: Marc Jacobs Daisy 50Ml 3Pc Gift Set | D9: MARC JACOBS
A10: Fragrance | B10: Ladies Fragrance Sets | C10: Marc Jacobs Perfect 50Ml 2Pc Gift Set | D10: MARC JACOBS
A11: Fragrance | B11: Ladies Fragrance Sets
A12: Fragrance | B12: Ladies Fragrance Sets
A13: Fragrance | B13: Ladies Fragrance Singles | C13: Boss Femme 75Ml Edp Spr | D13: Hugo Boss
A14: Fragrance | B14: Ladies Fragrance Singles | C14: Boss The Scent Ladies 50Ml Edp Spray | D14: Hugo Boss
A15: Fragrance | B15: Ladies Fragrance Singles | C15: Burberry For Women (Original) 100Ml Edp Spray | D15: Burberry
A16: Fragrance | B16: Ladies Fragrance Singles | C16: Cacharel Yes I Am Pink 50Ml Edp Spr | D16: Cacharel
A17: Fragrance | B17: Ladies Fragrance Singles | C17: Chance Eau Tendre Edp Spray 50Ml | D17: Chanel
A18: Fragrance | B18: Ladies Fragrance Singles | C18: Chanel Chance Eau De Parfum 100Ml | D18: Chanel
A19: Fragrance | B19: Ladies Fragrance Singles | C19: Chanel Chance Eau De Parfum 50Ml | D19: Chanel
A20: Fragrance | B20: Ladies Fragrance Singles | C20: Chanel Chance Eau Tendre Eau De Toilette 50Ml | D20: Chanel
A21: Fragrance | B21: Ladies Fragrance Singles | C21: Chanel Coco Mademoiselle Eau De Parfum 35Ml | D21: Chanel
A22: Fragrance | B22: Ladies Fragrance Singles | C22: Chanel Coco Mademoiselle Eau De Parfum 50Ml | D22: Chanel
A23: Fragrance | B23: Ladies Fragrance Singles | C23: Chanel No5 Eau De Parfum 100Ml | D23: Chanel
A24: Fragrance | B24: Ladies Fragrance Singles | C24: Chanel No5 Eau De Parfum 35Ml | D24: Chanel
... A43: Fragrance | B43: Ladies Fragrance Singles | C43: Vera Wang Princess 100Ml Edt Spr | D43: Vera Wang
A44: Fragrance | B44: Ladies Fragrance Singles
A45: Fragrance | B45: Ladies Fragrance Singles
A46: Fragrance | B46: Mens Fragrance Sets | C46: Boss The Scent Mens 100Ml 2Pc Gift Set | D46: Hugo Boss
A47: Fragrance | B47: Mens Fragrance Sets | C47: Diesel D By Diesel 50Ml 2Pc Gift Set | D47: Diesel
A48: Fragrance | B48: Mens Fragrance Sets | C48: Paco Rabanne 4Pc Miniature Gift Set | D48: PACO RABANNE
A49: Fragrance | B49: Mens Fragrance Sets
A50: Fragrance | B50: Mens Fragrance Sets
A51: Fragrance | B51: Mens Fragrance Singles | C51: Armani Code Mens 50Ml Edt Spr | D51: ARMANI
A52: Fragrance | B52: Mens Fragrance Singles | C52: Bleu De Chanel Edp 100Ml | D52: Chanel
A53: Fragrance | B53: Mens Fragrance Singles | C53: Bleu De Chanel Edp 50Ml | D53: Chanel
A54: Fragrance | B54: Mens Fragrance Singles | C54: Boss Bottled (Grey) 50Ml Edt Spr | D54: Hugo Boss
A55: Fragrance | B55: Mens Fragrance Singles | C55: Boss Bottled Tonic Mens 50Ml Edt | D55: Hugo Boss
A56: Fragrance | B56: Mens Fragrance Singles | C56: Boss Orange Mens 100Ml Edt Spr | D56: Hugo Boss
A57: Fragrance | B57: Mens Fragrance Singles | C57: Ck Eternity Mens 100Ml Edt Spr | D57: CALVIN KLEIN
A58: Fragrance | B58: Mens Fragrance Singles | C58: Ck Euphoria Mens 100Ml Edt Spr | D58: CALVIN KLEIN
...

Sheet Confirm Medicines & Health
A1: Page on the website | B1: Product | C1: Brand | D1: Our suggestion | E1: Pharmacist: belongs here? | F1: Notes (optional)
A2: Antiseptics & Wound Cleaning | B2: Dettol Antiseptic Liquid 750Ml | C2: Dettol | D2: Yes
A3: Antiseptics & Wound Cleaning | B3: Savlon Antiseptic Cream 30G | C3: Savlon | D3: Yes
A4: Antiseptics & Wound Cleaning | B4: Savlon Antiseptic Cream 60G | C4: Savlon | D4: Yes
A5: Athletes Foot | B5: Mycosan Athletes Foot Gel | C5: Mycosan | D5: Yes
A6: Bandages & Plasters | B6: Medi Spray Plaster 32.5Ml Can509 | C6: Medicare | D6: Yes
A7: Bandages & Plasters | B7: Medicare Blister Plasters 6Pk Medium | C7: Medicare | D7: Yes
A8: Bandages & Plasters | B8: Medicare Blister Plasters Assort 6Pk | C8: Medicare | D8: Yes
A9: Bandages & Plasters | B9: Medicare Blue Detectable Plasters 1 Size 100 Pk | C9: Medicare | D9: Yes
A10: Bandages & Plasters | B10: Medicare Fabric Assorted Plasters 30Pk | C10: Medicare | D10: Yes
A11: Bandages & Plasters | B11: Medicare Fabric Long Finger Plaster | C11: Medicare | D11: Yes
A12: Bandages & Plasters | B12: Medicare Fabric Plasters 30Pk | C12: Medicare | D12: Yes
A13: Bandages & Plasters | B13: Medicare Family Pack Fabric 50+ Assorted Plasters | C13: Medicare | D13: Yes
... A42: Cold & Flu Combination Products | B42: Nurofen Cold And Flu Tabs 24Pk | C42: Nurofen | D42: Yes
A43: Cold & Flu Combination Products | B43: Avogel Echinaforce Cold & Flu Drops 100Ml | C43: A.VOGEL | D43: Not sure | F43: a herbal remedy, not a combination product
A44: Cold & Flu Combination Products | B44: Avogel Echinaforce Cold & Flu Drops 50Ml | C44: A.VOGEL | D44: Not sure | F44: a herbal remedy, not a combination product
A45: Continence Care | B45: Tena Lady Discreet Med Pant 6Pk | C45: Quest | D45: Yes | F45: inherited from sub-page Pants
A46: Continence Care | B46: Tena Lady Pants Discreet Large 5Pk | C46: Tena | D46: Yes | F46: inherited from sub-page Pants
A47: Continence Care | B47: Tena Pants Plus (Extra Large) | C47: Tena | D47: Yes | F47: inherited from sub-page Pants
A48: Corn & Callous Care | B48: Carnation Callous Caps 2Pk | C48: Carnation | D48: Yes
A49: Corn & Callous Care | B49: Carnation Corn Caps 5Pk | C49: Carnation | D49: Yes
A50: Corn & Callous Care | B50: Carnation Corn Pads 9Pk | C50: Carnation | D50: Yes
A51: Corn & Callous Care | B51: Carnation Corn Shields | C51: Carnation | D51: Yes
A52: Corn & Callous Care | B52: Scholl Corn Removal Plasters Waterproof | C52: Scholl | D52: Yes
A53: Cough | B53: Benylin 125Ml Chesty Cough N/D | C53: Benylin | D53: Yes
A54: Cough | B54: Benylin 125Ml Cough Med Orginal | C54: Benylin | D54: Yes
A55: Cough | B55: Benylin 125Ml Dry Cough Syrup | C55: Benylin | D55: Yes
A56: Cough | B56: Broncho Stop Junior Cough Strawberry 120Ml | C56: Bronchostop | D56: Yes
A57: Cough | B57: Buttercup Broncho Stop Cough Pastilles 10Pk | C57: Bronchostop | D57: Yes
A58: Cough | B58: Buttercup Broncho Stop Cough Syrup 120Ml | C58: Bronchostop | D58: Yes
A59: Cough | B59: Buttercup Broncho Stop Cough Syrup 200Ml | C59: Bronchostop | D59: Yes
... A77: Ear Care & Earplugs | B77: Tropex 5% Ear Drops 10Ml | C77: Tropex | D77: Yes
A78: Electrical Healthcare | B78: Medicare Digital Pulse Oximeter | C78: Medicare | D78: Yes | F78: inherited from sub-page Oximeters & Weighing Scales
A79: Foot Soak & Odour Control | B79: Foot Soak Bundle | C79: McCormack's Pharmacy | D79: Yes
A80: Gum Health & Gingivitis | B80: Spotlight Toothpaste For Gum Health 100Ml | C80: Spotlight | D80: Yes
A81: Hair Loss | B81: Phyto Anti Hair Loss Treatment For Women (Progressive Hair-Loss: Ageing, Menopause, Heredity) | C81: Phyto | D81: Yes
A82: Hair Loss | B82: Phyto Anti Hair Loss Treatment For Women (Reactional Hair-Loss: Stress, Diet, Post-Preg) | C82: Phyto | D82: Yes
A83: Hair Loss | B83: Phyto Phytocyane Anti Hair Loss Treatment For Men | C83: Phyto | D83: Yes
A84: Irritated & Damaged Skin | B84: Sudocrem Tub 60G | C84: Sudocrem | D84: Not sure | F84: Licensed medicine (GSL). Should it sit on this skincare page?
A85: Irritated & Damaged Skin | B85: Sudocrem Tub 125G | C85: Sudocrem | D85: Not sure | F85: Licensed medicine (GSL). Should it sit on this skincare page?
...

Sheet Check licence
A1: Product | B1: Brand | C1: What we found on the HPRA register | D1: Why we are asking | E1: Pharmacist: how is it licensed? | F1: Notes (optional)
A2: Corsodyl 50G Dental Gel | B2: Corsodyl | C2: Only the Corsodyl 0.2% mouthwash licence (PA0678/002/004, GSL). We found no licence for the dental gel itself. | D2: Our list marks the gel pharmacy-only (P), but the licence we matched is general sale (GSL) and is for a different product.

Sheet Decisions
A1: Product | B1: On the website now | C1: What we found on the HPRA register | D1: Decision we need from you | E1: Pharmacist: your decision | F1: Notes (optional)
A2: Calpol Infant 140Ml Spoon/ Syringe Strawberry Susp; Calpol Infant Sf 140Ml Spoon Syringe S/Berry Susp | B2: The first is on the website; the sugar-free one is not. The website lets a customer put any number in the bag. | C2: Calpol Infant is general sale only in packs of up to 60 ml, one pack per sale. A 140 ml pack is pharmacy only, at most two packs per sale (PA23490/003/001). | D2: What is the most one website order may contain? The licence allows two. Tell us the number and we will set it. The same limits apply to Calpol 6+ 140 ml and to the website's other paracetamol products; tell us whether you want one limit across all of them.
A3: E45 Cream 50G; E45 Cream 125G | B3: The 50 g is on the website; the 125 g is not. | C3: E45 Cream, PA22650/007/001: a licensed medicine, general sale. | D3: E45 Cream is a licensed medicine, so it is marked as one, and like every medicine its website orders will wait for your review. It had been missed because our search of the register did not recognise its title. Please check that the pack you stock shows PA22650/007/001, and tell us if it shows something else.
A4: Tefin 75Mg Ibuprofen Suppositories | B4: No. Taken off the website (set to draft) on 26 September until its description is corrected. | C4: Tefin 75 mg Suppositories, PA0126/330/001: pharmacy only, packs of up to 50. | D4: Its website description is Tefin 150 mg's text, and says "must be aged over 18" and "maximum five packs per order". Please send us the correct description from the Tefin 75 mg leaflet, or tell us what it should say. We have not rewritten it ourselves.
A5: Zirtek Tabs 10Mg 30Pk | B5: Yes. | C5: Two Zirtek tablet licences: Zirtek Allergy Relief 10 mg (PA0891/008/005) allows up to 30 tablets without prescription, pharmacy only. Zirtek 10 mg film-coated tablets (PA0891/008/002) is prescription only above 7 tablets. | D5: Which licence number is on the box we sell? If it is PA0891/008/002, a 30-pack needs a prescription and must come off the website.
A6: Quantity-limit app (Minmaxify Premium or Avada Order Limits) | B6: Not installed. | C6: Several licences cap how many packs one sale may contain: one pseudoephedrine product per sale; one general-sale paracetamol pack, or two pharmacy-size packs. The website does not enforce any of this, and a limit in the website's own pages is easy to get round. | D6: Should we add an App Store app, Minmaxify Premium or Avada Order Limits, at about $20 a month? It checks the limits at checkout itself, including Apple Pay and Shop Pay, so an order over a limit cannot be placed on the website. Without it, once the pharmacist hold is built, every medicine order waits for your review, so you would catch an over-limit order then and cancel or reduce it. The limits it would apply are in 6-Quantity-Limit-Tags-Draft.csv: please confirm the products and the most per order.

Sheet Medicine classification
A1: Group | B1: Product | C1: Brand | D1: Category on the website | E1: HPRA register | F1: Our classification | G1: Is our classification right? | H1: Notes (optional)
A2: 1. Licensed: pharmacy only (P) | B2: Anti Hist Allergy 10Mg Tabs 30Pk | C2: Anti Hist | D2: Allergy Relief | E2: Anti-Hist Allergy 10mg Film-coated tablets [PA0126/267/001, P] | F2: Pharmacy-only
A3: 1. Licensed: pharmacy only (P) | B3: Beconase Hayfever 100 Dose | C3: Beconase | D3: Allergy Relief | E3: Beconase Hayfever nasal spray 50 micrograms per spray [PA1186/008/001, P] | F3: Pharmacy-only
A4: 1. Licensed: pharmacy only (P) | B4: Cetrine Allergy Cetirizine 1Mg/Ml 200Ml | C4: Cetrine | D4: Allergy Relief | E4: Cetrine Allergy 1 mg/ml oral solution [PA0711/075/003, P] | F4: Pharmacy-only
A5: 1. Licensed: pharmacy only (P) | B5: Cetrine Allergy Cetirizine 30Pk | C5: Cetrine | D5: Allergy Relief | E5: Cetrine Allergy 1 mg/ml oral solution [PA0711/075/003, P] | F5: Pharmacy-only
A6: 1. Licensed: pharmacy only (P) | B6: Cetrine Allergy Cetirizine 7Pk | C6: Cetrine | D6: Allergy Relief | E6: Cetrine Allergy 1 mg/ml oral solution [PA0711/075/003, P] | F6: Pharmacy-only
A7: 1. Licensed: pharmacy only (P) | B7: Clarityn Tabs Loratadine 30Pk | C7: Clarityn | D7: Allergy Relief | E7: Clarityn 10 mg Tablets [PA1410/075/001, P] | F7: Pharmacy-only
A8: 1. Licensed: pharmacy only (P) | B8: Clarityn Tabs Loratadine 7Pk | C8: Clarityn | D8: Allergy Relief | E8: Clarityn 10 mg Tablets [PA1410/075/001, P] | F8: Pharmacy-only
A9: 1. Licensed: pharmacy only (P) | B9: Lorat 10Mg Tabs 28Pk | C9: Lorat | D9: Allergy Relief | E9: Lorat 10mg Tablets [PA0711/088/001, P] | F9: Pharmacy-only
A10: 1. Licensed: pharmacy only (P) | B10: Lorat 10Mg Tabs 7Pk | C10: Lorat | D10: Allergy Relief | E10: Lorat 10mg Tablets [PA0711/088/001, P] | F10: Pharmacy-only
A11: 1. Licensed: pharmacy only (P) | B11: Nasacort Allergy Nasal Spray | C11: Nasacort | D11: Allergy Relief | E11: Nasacort Allergy 55 micrograms/dose nasal spray, suspension [PA23180/001/002, P] | F11: Pharmacy-only
A12: 1. Licensed: pharmacy only (P) | B12: Phenergan Elixir 100Ml | C12: Phenergan | D12: Allergy Relief | E12: Phenergan 5 mg/5 ml oral solution [PA23180/011/001, P] | F12: Pharmacy-only
A13: 1. Licensed: pharmacy only (P) | B13: Telfast Allergy 120Mg Tabs 30Pk | C13: Telfast | D13: Allergy Relief | E13: Telfast Allergy 120 mg film-coated tablets [PA23180/014/001, P] | F13: Pharmacy-only
... A342: 3. Possible match on the register | B342: Milk Of Magnesia 200Ml | C342: Milk Of Magnesia | D342: Stomach & Digestion | E342: Milk of Magnesia Traditional Mint Flavoured Liquid, 415 mg/5 ml oral suspension [PA1186/01 | F342: Not sure
A343: 4. Veterinary medicines | B343: Fleaway Plus Cat | C343: Fleaway Plus | D343: Companion Animal | E343: Veterinary medicine; not on the human register | F343: Veterinary medicine | G343: Veterinary medicine
A344: 4. Veterinary medicines | B344: Fleaway Plus Large Dog | C344: Fleaway Plus | D344: Companion Animal | E344: Veterinary medicine; not on the human register | F344: Veterinary medicine | G344: Veterinary medicine
A345: 4. Veterinary medicines | B345: Fleaway Plus Medium Dog | C345: Fleaway Plus | D345: Companion Animal | E345: Veterinary medicine; not on the human register | F345: Veterinary medicine | G345: Veterinary medicine
A346: 4. Veterinary medicines | B346: Fleaway Plus Small Dog | C346: Fleaway Plus | D346: Companion Animal | E346: Veterinary medicine; not on the human register | F346: Veterinary medicine | G346: Veterinary medicine
A347: 4. Veterinary medicines | B347: Fleaway Plus X-Large Dog | C347: Fleaway Plus | D347: Companion Animal | E347: Veterinary medicine; not on the human register | F347: Veterinary medicine | G347: Veterinary medicine
